<?xml version="1.0" encoding="UTF-8"?>
<!-- Generated by org.testng.reporters.JUnitReportReporter -->
<testsuite hostname="Dell-Vostro-2520" failures="1" tests="5" name="extent.report2.Functionality1" time="10.840" errors="1" timestamp="2021-08-25T21:24:38 IST" skipped="3">
  <testcase classname="extent.report2.Functionality1" name="functionality1Test1" time="0.003">
    <skipped/>
  </testcase> <!-- functionality1Test1 -->
  <system-out/>
  <testcase classname="extent.report2.Functionality1" name="functionality1Test3" time="0.000">
    <skipped/>
  </testcase> <!-- functionality1Test3 -->
  <system-out/>
  <testcase classname="extent.report2.Functionality1" name="functionality1Test2" time="0.000">
    <skipped/>
  </testcase> <!-- functionality1Test2 -->
  <system-out/>
  <testcase classname="extent.report2.Functionality1" name="getResult" time="0.019">
    <error message="Cannot invoke &quot;com.aventstack.extentreports.ExtentTest.log(com.aventstack.extentreports.Status, com.aventstack.extentreports.markuputils.Markup)&quot; because &quot;extent.report2.BaseTest.test&quot; is null" type="java.lang.NullPointerException">
      <![CDATA[java.lang.NullPointerException: Cannot invoke "com.aventstack.extentreports.ExtentTest.log(com.aventstack.extentreports.Status, com.aventstack.extentreports.markuputils.Markup)" because "extent.report2.BaseTest.test" is null
at extent.report2.BaseTest.getResult(BaseTest.java:48)
at java.base/jdk.internal.reflect.NativeMethodAccessorImpl.invoke0(Native Method)
at java.base/jdk.internal.reflect.NativeMethodAccessorImpl.invoke(NativeMethodAccessorImpl.java:64)
at java.base/jdk.internal.reflect.DelegatingMethodAccessorImpl.invoke(DelegatingMethodAccessorImpl.java:43)
at java.base/java.lang.reflect.Method.invoke(Method.java:564)
at org.testng.internal.MethodInvocationHelper.invokeMethod(MethodInvocationHelper.java:133)
at org.testng.internal.MethodInvocationHelper.invokeMethodConsideringTimeout(MethodInvocationHelper.java:62)
at org.testng.internal.ConfigInvoker.invokeConfigurationMethod(ConfigInvoker.java:385)
at org.testng.internal.ConfigInvoker.invokeConfigurations(ConfigInvoker.java:321)
at org.testng.internal.TestInvoker.runConfigMethods(TestInvoker.java:700)
at org.testng.internal.TestInvoker.runAfterGroupsConfigurations(TestInvoker.java:676)
at org.testng.internal.TestInvoker.invokeMethod(TestInvoker.java:660)
at org.testng.internal.TestInvoker.invokeTestMethod(TestInvoker.java:173)
at org.testng.internal.MethodRunner.runInSequence(MethodRunner.java:46)
at org.testng.internal.TestInvoker$MethodInvocationAgent.invoke(TestInvoker.java:824)
at org.testng.internal.TestInvoker.invokeTestMethods(TestInvoker.java:146)
at org.testng.internal.TestMethodWorker.invokeTestMethods(TestMethodWorker.java:146)
at org.testng.internal.TestMethodWorker.run(TestMethodWorker.java:128)
at java.base/java.util.ArrayList.forEach(ArrayList.java:1511)
at org.testng.TestRunner.privateRun(TestRunner.java:794)
at org.testng.TestRunner.run(TestRunner.java:596)
at org.testng.SuiteRunner.runTest(SuiteRunner.java:377)
at org.testng.SuiteRunner.runSequentially(SuiteRunner.java:371)
at org.testng.SuiteRunner.privateRun(SuiteRunner.java:332)
at org.testng.SuiteRunner.run(SuiteRunner.java:276)
at org.testng.SuiteRunnerWorker.runSuite(SuiteRunnerWorker.java:53)
at org.testng.SuiteRunnerWorker.run(SuiteRunnerWorker.java:96)
at org.testng.TestNG.runSuitesSequentially(TestNG.java:1212)
at org.testng.TestNG.runSuitesLocally(TestNG.java:1134)
at org.testng.TestNG.runSuites(TestNG.java:1063)
at org.testng.TestNG.run(TestNG.java:1031)
at org.testng.remote.AbstractRemoteTestNG.run(AbstractRemoteTestNG.java:115)
at org.testng.remote.RemoteTestNG.initAndRun(RemoteTestNG.java:251)
at org.testng.remote.RemoteTestNG.main(RemoteTestNG.java:77)
]]>
    </error>
  </testcase> <!-- getResult -->
  <system-out/>
  <testcase classname="extent.report2.Functionality1" name="failedTest" time="10.818">
    <failure message="expected:&lt;true&gt; but was:&lt;false&gt;" type="java.lang.AssertionError">
      <![CDATA[java.lang.AssertionError: expected:<true> but was:<false>
at org.testng.AssertJUnit.fail(AssertJUnit.java:65)
at org.testng.AssertJUnit.failNotEquals(AssertJUnit.java:468)
at org.testng.AssertJUnit.assertEquals(AssertJUnit.java:88)
at org.testng.AssertJUnit.assertEquals(AssertJUnit.java:230)
at org.testng.AssertJUnit.assertEquals(AssertJUnit.java:240)
at extent.report2.Functionality1.failedTest(Functionality1.java:37)
at java.base/jdk.internal.reflect.NativeMethodAccessorImpl.invoke0(Native Method)
at java.base/jdk.internal.reflect.NativeMethodAccessorImpl.invoke(NativeMethodAccessorImpl.java:64)
at java.base/jdk.internal.reflect.DelegatingMethodAccessorImpl.invoke(DelegatingMethodAccessorImpl.java:43)
at java.base/java.lang.reflect.Method.invoke(Method.java:564)
at org.testng.internal.MethodInvocationHelper.invokeMethod(MethodInvocationHelper.java:133)
at org.testng.internal.TestInvoker.invokeMethod(TestInvoker.java:598)
at org.testng.internal.TestInvoker.invokeTestMethod(TestInvoker.java:173)
at org.testng.internal.MethodRunner.runInSequence(MethodRunner.java:46)
at org.testng.internal.TestInvoker$MethodInvocationAgent.invoke(TestInvoker.java:824)
at org.testng.internal.TestInvoker.invokeTestMethods(TestInvoker.java:146)
at org.testng.internal.TestMethodWorker.invokeTestMethods(TestMethodWorker.java:146)
at org.testng.internal.TestMethodWorker.run(TestMethodWorker.java:128)
at java.base/java.util.ArrayList.forEach(ArrayList.java:1511)
at org.testng.TestRunner.privateRun(TestRunner.java:794)
at org.testng.TestRunner.run(TestRunner.java:596)
at org.testng.SuiteRunner.runTest(SuiteRunner.java:377)
at org.testng.SuiteRunner.runSequentially(SuiteRunner.java:371)
at org.testng.SuiteRunner.privateRun(SuiteRunner.java:332)
at org.testng.SuiteRunner.run(SuiteRunner.java:276)
at org.testng.SuiteRunnerWorker.runSuite(SuiteRunnerWorker.java:53)
at org.testng.SuiteRunnerWorker.run(SuiteRunnerWorker.java:96)
at org.testng.TestNG.runSuitesSequentially(TestNG.java:1212)
at org.testng.TestNG.runSuitesLocally(TestNG.java:1134)
at org.testng.TestNG.runSuites(TestNG.java:1063)
at org.testng.TestNG.run(TestNG.java:1031)
at org.testng.remote.AbstractRemoteTestNG.run(AbstractRemoteTestNG.java:115)
at org.testng.remote.RemoteTestNG.initAndRun(RemoteTestNG.java:251)
at org.testng.remote.RemoteTestNG.main(RemoteTestNG.java:77)
]]>
    </failure>
  </testcase> <!-- failedTest -->
  <system-out/>
</testsuite> <!-- extent.report2.Functionality1 -->
